Workbook

Sheet Dashboard
B1: OVERALL MONEY DASHBOARD
P2: Category | Q2: Amount
B3: Track your total money across banks, e-wallets, and cash, including estimated interest growth. | P3: Bank | Q3: =SUMIFS(Accounts!$K$6:$K$17,Accounts!$M$6:$M$17,"Yes",Accounts!$C$6:$C$17,"Bank")
P4: E-Wallet | Q4: =SUMIFS(Accounts!$K$6:$K$17,Accounts!$M$6:$M$17,"Yes",Accounts!$C$6:$C$17,"E-Wallet")
B5: TOTAL MONEY | E5: BANK BALANCE | H5: E-WALLET BALANCE | K5: INTEREST ACCRUED | P5: Cash / Other | Q5: =SUMIFS(Accounts!$K$6:$K$17,Accounts!$M$6:$M$17,"Yes",Accounts!$C$6:$C$17,"Cash / Other")
B6: =SUMIF(Accounts!$M$6:$M$17,"Yes",Accounts!$K$6:$K$17) | E6: =SUMIFS(Accounts!$K$6:$K$17,Accounts!$M$6:$M$17,"Yes",Accounts!$C$6:$C$17,"Bank") | H6: =SUMIFS(Accounts!$K$6:$K$17,Accounts!$M$6:$M$17,"Yes",Accounts!$C$6:$C$17,"E-Wallet") | K6: =SUMIF(Accounts!$M$6:$M$17,"Yes",Accounts!$J$6:$J$17) | P6: Excluded | Q6: =SUMIF(Accounts!$M$6:$M$17,"No",Accounts!$K$6:$K$17)
B9: Recorded balances plus estimated interest | E9: Calculated savings and checking balances | H9: Calculated digital wallet balances | K9: Estimated growth since each last update
P10: Snapshot Date | Q10: Total Money
B11: ACCOUNT BREAKDOWN | P11: =TEXT('Balance History'!B6,"mmm yy") | Q11: ='Balance History'!F6
B12: Account | C12: Type | D12: Institution | E12: Calculated Balance (₱) | F12: % of Total | G12: Accrued Interest (₱) | H12: Last Updated | P12: =TEXT('Balance History'!B7,"mmm yy") | Q12: ='Balance History'!F7
B13: =IF(Accounts!B6="","",Accounts!B6) | C13: =IF(Accounts!B6="","",Accounts!C6) | D13: =IF(Accounts!B6="","",Accounts!D6) | E13: =IF(B13="","",IF(Accounts!M6="Yes",Accounts!K6,"Excluded")) | F13: =IF(B13="","",IFERROR(IF(Accounts!M6="Yes",Accounts!K6,0)/SUMIF(Accounts!$M$6:$M$17,"Yes",Accounts!$K$6:$K$17),0)) | G13: =IF(B13="","",IF(Accounts!M6="Yes",Accounts!J6,0)) | H13: =IF(Accounts!B6="","",Accounts!L6) | P13: =TEXT('Balance History'!B8,"mmm yy") | Q13: ='Balance History'!F8
B14: =IF(Accounts!B7="","",Accounts!B7) | C14: =IF(Accounts!B7="","",Accounts!C7) | D14: =IF(Accounts!B7="","",Accounts!D7) | E14: =IF(B14="","",IF(Accounts!M7="Yes",Accounts!K7,"Excluded")) | F14: =IF(B14="","",IFERROR(IF(Accounts!M7="Yes",Accounts!K7,0)/SUMIF(Accounts!$M$6:$M$17,"Yes",Accounts!$K$6:$K$17),0)) | G14: =IF(B14="","",IF(Accounts!M7="Yes",Accounts!J7,0)) | H14: =IF(Accounts!B7="","",Accounts!L7) | P14: =TEXT('Balance History'!B9,"mmm yy") | Q14: ='Balance History'!F9
B15: =IF(Accounts!B8="","",Accounts!B8) | C15: =IF(Accounts!B8="","",Accounts!C8) | D15: =IF(Accounts!B8="","",Accounts!D8) | E15: =IF(B15="","",IF(Accounts!M8="Yes",Accounts!K8,"Excluded")) | F15: =IF(B15="","",IFERROR(IF(Accounts!M8="Yes",Accounts!K8,0)/SUMIF(Accounts!$M$6:$M$17,"Yes",Accounts!$K$6:$K$17),0)) | G15: =IF(B15="","",IF(Accounts!M8="Yes",Accounts!J8,0)) | H15: =IF(Accounts!B8="","",Accounts!L8) | P15: =TEXT('Balance History'!B10,"mmm yy") | Q15: ='Balance History'!F10
B16: =IF(Accounts!B9="","",Accounts!B9) | C16: =IF(Accounts!B9="","",Accounts!C9) | D16: =IF(Accounts!B9="","",Accounts!D9) | E16: =IF(B16="","",IF(Accounts!M9="Yes",Accounts!K9,"Excluded")) | F16: =IF(B16="","",IFERROR(IF(Accounts!M9="Yes",Accounts!K9,0)/SUMIF(Accounts!$M$6:$M$17,"Yes",Accounts!$K$6:$K$17),0)) | G16: =IF(B16="","",IF(Accounts!M9="Yes",Accounts!J9,0)) | H16: =IF(Accounts!B9="","",Accounts!L9) | P16: =TEXT('Balance History'!B11,"mmm yy") | Q16: ='Balance History'!F11
B17: =IF(Accounts!B10="","",Accounts!B10) | C17: =IF(Accounts!B10="","",Accounts!C10) | D17: =IF(Accounts!B10="","",Accounts!D10) | E17: =IF(B17="","",IF(Accounts!M10="Yes",Accounts!K10,"Excluded")) | F17: =IF(B17="","",IFERROR(IF(Accounts!M10="Yes",Accounts!K10,0)/SUMIF(Accounts!$M$6:$M$17,"Yes",Accounts!$K$6:$K$17),0)) | G17: =IF(B17="","",IF(Accounts!M10="Yes",Accounts!J10,0)) | H17: =IF(Accounts!B10="","",Accounts!L10) | P17: =TEXT('Balance History'!B12,"mmm yy") | Q17: ='Balance History'!F12
B18: =IF(Accounts!B11="","",Accounts!B11) | C18: =IF(Accounts!B11="","",Accounts!C11) | D18: =IF(Accounts!B11="","",Accounts!D11) | E18: =IF(B18="","",IF(Accounts!M11="Yes",Accounts!K11,"Excluded")) | F18: =IF(B18="","",IFERROR(IF(Accounts!M11="Yes",Accounts!K11,0)/SUMIF(Accounts!$M$6:$M$17,"Yes",Accounts!$K$6:$K$17),0)) | G18: =IF(B18="","",IF(Accounts!M11="Yes",Accounts!J11,0)) | H18: =IF(Accounts!B11="","",Accounts!L11)
B19: =IF(Accounts!B12="","",Accounts!B12) | C19: =IF(Accounts!B12="","",Accounts!C12) | D19: =IF(Accounts!B12="","",Accounts!D12) | E19: =IF(B19="","",IF(Accounts!M12="Yes",Accounts!K12,"Excluded")) | F19: =IF(B19="","",IFERROR(IF(Accounts!M12="Yes",Accounts!K12,0)/SUMIF(Accounts!$M$6:$M$17,"Yes",Accounts!$K$6:$K$17),0)) | G19: =IF(B19="","",IF(Accounts!M12="Yes",Accounts!J12,0)) | H19: =IF(Accounts!B12="","",Accounts!L12)
B20: =IF(Accounts!B13="","",Accounts!B13) | C20: =IF(Accounts!B13="","",Accounts!C13) | D20: =IF(Accounts!B13="","",Accounts!D13) | E20: =IF(B20="","",IF(Accounts!M13="Yes",Accounts!K13,"Excluded")) | F20: =IF(B20="","",IFERROR(IF(Accounts!M13="Yes",Accounts!K13,0)/SUMIF(Accounts!$M$6:$M$17,"Yes",Accounts!$K$6:$K$17),0)) | G20: =IF(B20="","",IF(Accounts!M13="Yes",Accounts!J13,0)) | H20: =IF(Accounts!B13="","",Accounts!L13)
B21: =IF(Accounts!B14="","",Accounts!B14) | C21: =IF(Accounts!B14="","",Accounts!C14) | D21: =IF(Accounts!B14="","",Accounts!D14) | E21: =IF(B21="","",IF(Accounts!M14="Yes",Accounts!K14,"Excluded")) | F21: =IF(B21="","",IFERROR(IF(Accounts!M14="Yes",Accounts!K14,0)/SUMIF(Accounts!$M$6:$M$17,"Yes",Accounts!$K$6:$K$17),0)) | G21: =IF(B21="","",IF(Accounts!M14="Yes",Accounts!J14,0)) | H21: =IF(Accounts!B14="","",Accounts!L14)
B22: =IF(Accounts!B15="","",Accounts!B15) | C22: =IF(Accounts!B15="","",Accounts!C15) | D22: =IF(Accounts!B15="","",Accounts!D15) | E22: =IF(B22="","",IF(Accounts!M15="Yes",Accounts!K15,"Excluded")) | F22: =IF(B22="","",IFERROR(IF(Accounts!M15="Yes",Accounts!K15,0)/SUMIF(Accounts!$M$6:$M$17,"Yes",Accounts!$K$6:$K$17),0)) | G22: =IF(B22="","",IF(Accounts!M15="Yes",Accounts!J15,0)) | H22: =IF(Accounts!B15="","",Accounts!L15)
B23: =IF(Accounts!B16="","",Accounts!B16) | C23: =IF(Accounts!B16="","",Accounts!C16) | D23: =IF(Accounts!B16="","",Accounts!D16) | E23: =IF(B23="","",IF(Accounts!M16="Yes",Accounts!K16,"Excluded")) | F23: =IF(B23="","",IFERROR(IF(Accounts!M16="Yes",Accounts!K16,0)/SUMIF(Accounts!$M$6:$M$17,"Yes",Accounts!$K$6:$K$17),0)) | G23: =IF(B23="","",IF(Accounts!M16="Yes",Accounts!J16,0)) | H23: =IF(Accounts!B16="","",Accounts!L16)
B24: =IF(Accounts!B17="","",Accounts!B17) | C24: =IF(Accounts!B17="","",Accounts!C17) | D24: =IF(Accounts!B17="","",Accounts!D17) | E24: =IF(B24="","",IF(Accounts!M17="Yes",Accounts!K17,"Excluded")) | F24: =IF(B24="","",IFERROR(IF(Accounts!M17="Yes",Accounts!K17,0)/SUMIF(Accounts!$M$6:$M$17,"Yes",Accounts!$K$6:$K$17),0)) | G24: =IF(B24="","",IF(Accounts!M17="Yes",Accounts!J17,0)) | H24: =IF(Accounts!B17="","",Accounts!L17)
B27: OVERALL MONEY TREND
B28: Snapshot Date | C28: Bank (₱) | D28: E-Wallet (₱) | E28: Cash / Other (₱) | F28: Total Money (₱)
B29: ='Balance History'!B6 | C29: =IF('Balance History'!C6="","","₱"&TEXT('Balance History'!C6,"#,##0")) | D29: =IF('Balance History'!D6="","","₱"&TEXT('Balance History'!D6,"#,##0")) | E29: =IF('Balance History'!E6="","","₱"&TEXT('Balance History'!E6,"#,##0")) | F29: =IF('Balance History'!F6="","","₱"&TEXT('Balance History'!F6,"#,##0"))
B30: ='Balance History'!B7 | C30: =IF('Balance History'!C7="","","₱"&TEXT('Balance History'!C7,"#,##0")) | D30: =IF('Balance History'!D7="","","₱"&TEXT('Balance History'!D7,"#,##0")) | E30: =IF('Balance History'!E7="","","₱"&TEXT('Balance History'!E7,"#,##0")) | F30: =IF('Balance History'!F7="","","₱"&TEXT('Balance History'!F7,"#,##0"))
B31: ='Balance History'!B8 | C31: =IF('Balance History'!C8="","","₱"&TEXT('Balance History'!C8,"#,##0")) | D31: =IF('Balance History'!D8="","","₱"&TEXT('Balance History'!D8,"#,##0")) | E31: =IF('Balance History'!E8="","","₱"&TEXT('Balance History'!E8,"#,##0")) | F31: =IF('Balance History'!F8="","","₱"&TEXT('Balance History'!F8,"#,##0"))
B32: ='Balance History'!B9 | C32: =IF('Balance History'!C9="","","₱"&TEXT('Balance History'!C9,"#,##0")) | D32: =IF('Balance History'!D9="","","₱"&TEXT('Balance History'!D9,"#,##0")) | E32: =IF('Balance History'!E9="","","₱"&TEXT('Balance History'!E9,"#,##0")) | F32: =IF('Balance History'!F9="","","₱"&TEXT('Balance History'!F9,"#,##0"))
B33: ='Balance History'!B10 | C33: =IF('Balance History'!C10="","","₱"&TEXT('Balance History'!C10,"#,##0")) | D33: =IF('Balance History'!D10="","","₱"&TEXT('Balance History'!D10,"#,##0")) | E33: =IF('Balance History'!E10="","","₱"&TEXT('Balance History'!E10,"#,##0")) | F33: =IF('Balance History'!F10="","","₱"&TEXT('Balance History'!F10,"#,##0"))
B34: ='Balance History'!B11 | C34: =IF('Balance History'!C11="","","₱"&TEXT('Balance History'!C11,"#,##0")) | D34: =IF('Balance History'!D11="","","₱"&TEXT('Balance History'!D11,"#,##0")) | E34: =IF('Balance History'!E11="","","₱"&TEXT('Balance History'!E11,"#,##0")) | F34: =IF('Balance History'!F11="","","₱"&TEXT('Balance History'!F11,"#,##0"))
B35: ='Balance History'!B12 | C35: =IF('Balance History'!C12="","","₱"&TEXT('Balance History'!C12,"#,##0")) | D35: =IF('Balance History'!D12="","","₱"&TEXT('Balance History'!D12,"#,##0")) | E35: =IF('Balance History'!E12="","","₱"&TEXT('Balance History'!E12,"#,##0")) | F35: =IF('Balance History'!F12="","","₱"&TEXT('Balance History'!F12,"#,##0"))
B38: HOW TO USE THIS TRACKER
B39: 1. Enter recorded balances, interest rates, rate basis, and dates in Accounts.
B40: 2. The Dashboard uses Calculated Balance Today, so estimated interest updates automatically.
B41: 3. Add a snapshot in Balance History whenever you want to preserve your progress.
B42: 4. Use Include in Total = No for accounts you do not want counted.

Sheet Accounts
B1: ACCOUNT BALANCES + INTEREST
B3: Enter the recorded balance, interest rate, rate basis, and last-updated date. Calculated columns estimate your current savings automatically.
N4: Status
B5: Account Name | C5: Account Type | D5: Institution | E5: Recorded Balance (₱) | F5: Interest Rate | G5: Rate Basis | H5: Est. Monthly Interest (₱) | I5: Est. Annual Interest (₱) | J5: Accrued Interest (₱) | K5: Calculated Balance Today (₱) | L5: Last Updated | M5: Include in Total | N5: Notes
B6: BPI Checking | C6: Bank | D6: BPI | E6: 45000 | F6: 0 | G6: Annual | H6: =IF(B6="","",IF(OR(E6="",F6="",G6=""),0,IF(G6="Annual",E6*((1+F6)^(1/12)-1),IF(G6="Monthly",E6*F6,0)))) | I6: =IF(B6="","",IF(OR(E6="",F6="",G6=""),0,IF(G6="Annual",E6*F6,IF(G6="Monthly",E6*((1+F6)^12-1),0)))) | J6: =IF(B6="","",IF(OR(E6="",F6="",G6="",L6=""),0,IF(TODAY()<=L6,0,IF(G6="Annual",E6*((1+F6)^((TODAY()-L6)/365)-1),IF(G6="Monthly",E6*((1+F6)^((TODAY()-L6)/(365/12))-1),0))))) | K6: =IF(B6="","",IFERROR(E6+J6,E6)) | L6: 46223 | M6: Yes | N6: =IF(B6="","",IF(OR(L6="",L6=""),"-",IF((TODAY()-L6)>30,"⚠️ Stale","✅ Current")))
B7: BDO Savings | C7: Bank | D7: BDO | E7: 120000 | F7: 0 | G7: Annual | H7: =IF(B7="","",IF(OR(E7="",F7="",G7=""),0,IF(G7="Annual",E7*((1+F7)^(1/12)-1),IF(G7="Monthly",E7*F7,0)))) | I7: =IF(B7="","",IF(OR(E7="",F7="",G7=""),0,IF(G7="Annual",E7*F7,IF(G7="Monthly",E7*((1+F7)^12-1),0)))) | J7: =IF(B7="","",IF(OR(E7="",F7="",G7="",L7=""),0,IF(TODAY()<=L7,0,IF(G7="Annual",E7*((1+F7)^((TODAY()-L7)/365)-1),IF(G7="Monthly",E7*((1+F7)^((TODAY()-L7)/(365/12))-1),0))))) | K7: =IF(B7="","",IFERROR(E7+J7,E7)) | L7: 46223 | M7: Yes | N7: =IF(B7="","",IF(OR(L7="",L7=""),"-",IF((TODAY()-L7)>30,"⚠️ Stale","✅ Current")))
B8: GCash | C8: E-Wallet | D8: GCash | E8: 6500 | F8: 0 | G8: Annual | H8: =IF(B8="","",IF(OR(E8="",F8="",G8=""),0,IF(G8="Annual",E8*((1+F8)^(1/12)-1),IF(G8="Monthly",E8*F8,0)))) | I8: =IF(B8="","",IF(OR(E8="",F8="",G8=""),0,IF(G8="Annual",E8*F8,IF(G8="Monthly",E8*((1+F8)^12-1),0)))) | J8: =IF(B8="","",IF(OR(E8="",F8="",G8="",L8=""),0,IF(TODAY()<=L8,0,IF(G8="Annual",E8*((1+F8)^((TODAY()-L8)/365)-1),IF(G8="Monthly",E8*((1+F8)^((TODAY()-L8)/(365/12))-1),0))))) | K8: =IF(B8="","",IFERROR(E8+J8,E8)) | L8: 46223 | M8: Yes | N8: =IF(B8="","",IF(OR(L8="",L8=""),"-",IF((TODAY()-L8)>30,"⚠️ Stale","✅ Current")))
B9: Maya | C9: E-Wallet | D9: Maya | E9: 8000 | F9: 0 | G9: Annual | H9: =IF(B9="","",IF(OR(E9="",F9="",G9=""),0,IF(G9="Annual",E9*((1+F9)^(1/12)-1),IF(G9="Monthly",E9*F9,0)))) | I9: =IF(B9="","",IF(OR(E9="",F9="",G9=""),0,IF(G9="Annual",E9*F9,IF(G9="Monthly",E9*((1+F9)^12-1),0)))) | J9: =IF(B9="","",IF(OR(E9="",F9="",G9="",L9=""),0,IF(TODAY()<=L9,0,IF(G9="Annual",E9*((1+F9)^((TODAY()-L9)/365)-1),IF(G9="Monthly",E9*((1+F9)^((TODAY()-L9)/(365/12))-1),0))))) | K9: =IF(B9="","",IFERROR(E9+J9,E9)) | L9: 46223 | M9: Yes | N9: =IF(B9="","",IF(OR(L9="",L9=""),"-",IF((TODAY()-L9)>30,"⚠️ Stale","✅ Current")))
B10: Cash on Hand | C10: Cash / Other | D10: Cash | E10: 3500 | F10: 0 | G10: Annual | H10: =IF(B10="","",IF(OR(E10="",F10="",G10=""),0,IF(G10="Annual",E10*((1+F10)^(1/12)-1),IF(G10="Monthly",E10*F10,0)))) | I10: =IF(B10="","",IF(OR(E10="",F10="",G10=""),0,IF(G10="Annual",E10*F10,IF(G10="Monthly",E10*((1+F10)^12-1),0)))) | J10: =IF(B10="","",IF(OR(E10="",F10="",G10="",L10=""),0,IF(TODAY()<=L10,0,IF(G10="Annual",E10*((1+F10)^((TODAY()-L10)/365)-1),IF(G10="Monthly",E10*((1+F10)^((TODAY()-L10)/(365/12))-1),0))))) | K10: =IF(B10="","",IFERROR(E10+J10,E10)) | L10: 46223 | M10: Yes | N10: =IF(B10="","",IF(OR(L10="",L10=""),"-",IF((TODAY()-L10)>30,"⚠️ Stale","✅ Current")))
H11: =IF(B11="","",IF(OR(E11="",F11="",G11=""),0,IF(G11="Annual",E11*((1+F11)^(1/12)-1),IF(G11="Monthly",E11*F11,0)))) | I11: =IF(B11="","",IF(OR(E11="",F11="",G11=""),0,IF(G11="Annual",E11*F11,IF(G11="Monthly",E11*((1+F11)^12-1),0)))) | J11: =IF(B11="","",IF(OR(E11="",F11="",G11="",L11=""),0,IF(TODAY()<=L11,0,IF(G11="Annual",E11*((1+F11)^((TODAY()-L11)/365)-1),IF(G11="Monthly",E11*((1+F11)^((TODAY()-L11)/(365/12))-1),0))))) | K11: =IF(B11="","",IFERROR(E11+J11,E11)) | N11: =IF(B11="","",IF(OR(L11="",L11=""),"-",IF((TODAY()-L11)>30,"⚠️ Stale","✅ Current")))
H12: =IF(B12="","",IF(OR(E12="",F12="",G12=""),0,IF(G12="Annual",E12*((1+F12)^(1/12)-1),IF(G12="Monthly",E12*F12,0)))) | I12: =IF(B12="","",IF(OR(E12="",F12="",G12=""),0,IF(G12="Annual",E12*F12,IF(G12="Monthly",E12*((1+F12)^12-1),0)))) | J12: =IF(B12="","",IF(OR(E12="",F12="",G12="",L12=""),0,IF(TODAY()<=L12,0,IF(G12="Annual",E12*((1+F12)^((TODAY()-L12)/365)-1),IF(G12="Monthly",E12*((1+F12)^((TODAY()-L12)/(365/12))-1),0))))) | K12: =IF(B12="","",IFERROR(E12+J12,E12)) | N12: =IF(B12="","",IF(OR(L12="",L12=""),"-",IF((TODAY()-L12)>30,"⚠️ Stale","✅ Current")))
H13: =IF(B13="","",IF(OR(E13="",F13="",G13=""),0,IF(G13="Annual",E13*((1+F13)^(1/12)-1),IF(G13="Monthly",E13*F13,0)))) | I13: =IF(B13="","",IF(OR(E13="",F13="",G13=""),0,IF(G13="Annual",E13*F13,IF(G13="Monthly",E13*((1+F13)^12-1),0)))) | J13: =IF(B13="","",IF(OR(E13="",F13="",G13="",L13=""),0,IF(TODAY()<=L13,0,IF(G13="Annual",E13*((1+F13)^((TODAY()-L13)/365)-1),IF(G13="Monthly",E13*((1+F13)^((TODAY()-L13)/(365/12))-1),0))))) | K13: =IF(B13="","",IFERROR(E13+J13,E13)) | N13: =IF(B13="","",IF(OR(L13="",L13=""),"-",IF((TODAY()-L13)>30,"⚠️ Stale","✅ Current")))
H14: =IF(B14="","",IF(OR(E14="",F14="",G14=""),0,IF(G14="Annual",E14*((1+F14)^(1/12)-1),IF(G14="Monthly",E14*F14,0)))) | I14: =IF(B14="","",IF(OR(E14="",F14="",G14=""),0,IF(G14="Annual",E14*F14,IF(G14="Monthly",E14*((1+F14)^12-1),0)))) | J14: =IF(B14="","",IF(OR(E14="",F14="",G14="",L14=""),0,IF(TODAY()<=L14,0,IF(G14="Annual",E14*((1+F14)^((TODAY()-L14)/365)-1),IF(G14="Monthly",E14*((1+F14)^((TODAY()-L14)/(365/12))-1),0))))) | K14: =IF(B14="","",IFERROR(E14+J14,E14)) | N14: =IF(B14="","",IF(OR(L14="",L14=""),"-",IF((TODAY()-L14)>30,"⚠️ Stale","✅ Current")))
H15: =IF(B15="","",IF(OR(E15="",F15="",G15=""),0,IF(G15="Annual",E15*((1+F15)^(1/12)-1),IF(G15="Monthly",E15*F15,0)))) | I15: =IF(B15="","",IF(OR(E15="",F15="",G15=""),0,IF(G15="Annual",E15*F15,IF(G15="Monthly",E15*((1+F15)^12-1),0)))) | J15: =IF(B15="","",IF(OR(E15="",F15="",G15="",L15=""),0,IF(TODAY()<=L15,0,IF(G15="Annual",E15*((1+F15)^((TODAY()-L15)/365)-1),IF(G15="Monthly",E15*((1+F15)^((TODAY()-L15)/(365/12))-1),0))))) | K15: =IF(B15="","",IFERROR(E15+J15,E15)) | N15: =IF(B15="","",IF(OR(L15="",L15=""),"-",IF((TODAY()-L15)>30,"⚠️ Stale","✅ Current")))
H16: =IF(B16="","",IF(OR(E16="",F16="",G16=""),0,IF(G16="Annual",E16*((1+F16)^(1/12)-1),IF(G16="Monthly",E16*F16,0)))) | I16: =IF(B16="","",IF(OR(E16="",F16="",G16=""),0,IF(G16="Annual",E16*F16,IF(G16="Monthly",E16*((1+F16)^12-1),0)))) | J16: =IF(B16="","",IF(OR(E16="",F16="",G16="",L16=""),0,IF(TODAY()<=L16,0,IF(G16="Annual",E16*((1+F16)^((TODAY()-L16)/365)-1),IF(G16="Monthly",E16*((1+F16)^((TODAY()-L16)/(365/12))-1),0))))) | K16: =IF(B16="","",IFERROR(E16+J16,E16)) | N16: =IF(B16="","",IF(OR(L16="",L16=""),"-",IF((TODAY()-L16)>30,"⚠️ Stale","✅ Current")))
H17: =IF(B17="","",IF(OR(E17="",F17="",G17=""),0,IF(G17="Annual",E17*((1+F17)^(1/12)-1),IF(G17="Monthly",E17*F17,0)))) | I17: =IF(B17="","",IF(OR(E17="",F17="",G17=""),0,IF(G17="Annual",E17*F17,IF(G17="Monthly",E17*((1+F17)^12-1),0)))) | J17: =IF(B17="","",IF(OR(E17="",F17="",G17="",L17=""),0,IF(TODAY()<=L17,0,IF(G17="Annual",E17*((1+F17)^((TODAY()-L17)/365)-1),IF(G17="Monthly",E17*((1+F17)^((TODAY()-L17)/(365/12))-1),0))))) | K17: =IF(B17="","",IFERROR(E17+J17,E17)) | N17: =IF(B17="","",IF(OR(L17="",L17=""),"-",IF((TODAY()-L17)>30,"⚠️ Stale","✅ Current")))
B20: 📊 SUMMARY
B21: Metric | C21: Value
B22: Recorded Balance Included | C22: =SUMIF($M$6:$M$17,"Yes",$E$6:$E$17)
B23: Accrued Interest | C23: =SUMIF($M$6:$M$17,"Yes",$J$6:$J$17)
B24: Calculated Total | C24: =SUMIF($M$6:$M$17,"Yes",$K$6:$K$17)
B25: Estimated Monthly Interest | C25: =SUMIF($M$6:$M$17,"Yes",$H$6:$H$17)
B26: Estimated Annual Interest | C26: =SUMIF($M$6:$M$17,"Yes",$I$6:$I$17)
B27: Bank Total | C27: =SUMIFS($K$6:$K$17,$M$6:$M$17,"Yes",$C$6:$C$17,"Bank")
B28: E-Wallet Total | C28: =SUMIFS($K$6:$K$17,$M$6:$M$17,"Yes",$C$6:$C$17,"E-Wallet")
B29: Cash / Other | C29: =SUMIFS($K$6:$K$17,$M$6:$M$17,"Yes",$C$6:$C$17,"Cash / Other")
B30: Active Accounts | C30: =COUNTIF($M$6:$M$17,"Yes")
B31: Avg Interest Rate (Annual) | C31: =IFERROR(AVERAGEIFS($I$6:$I$17,$M$6:$M$17,"Yes",$I$6:$I$17,">0")/AVERAGEIFS($E$6:$E$17,$M$6:$M$17,"Yes",$E$6:$E$17,">0"),0)
B32: Top Earning Account | C32: =IFERROR(INDEX($B$6:$B$17,MATCH(MAX($I$6:$I$17),$I$6:$I$17,0)),"—")
B33: Stale Accounts (>30 days) | C33: =COUNTIF($N$6:$N$17,"⚠️ Stale")

Sheet Balance History
B1: BALANCE HISTORY
B3: Add one row whenever you want to save a weekly or monthly snapshot. Use the calculated category totals that already include estimated interest.
B5: Snapshot Date | C5: Bank Total (₱) | D5: E-Wallet Total (₱) | E5: Cash / Other (₱) | F5: Total Money (₱) | G5: Change (₱) | H5: Change (%) | I5: Ann. Growth (%)
B6: 46053 | C6: 135000 | D6: 9000 | E6: 3000 | F6: =IF(B6="","",SUM(C6:E6)) | G6: ="" | H6: ="" | I6: =""
B7: 46081 | C7: 140000 | D7: 9800 | E7: 3200 | F7: =IF(B7="","",SUM(C7:E7)) | G7: =IF(B7="","",IFERROR(F7-F6,"")) | H7: =IF(B7="","",IFERROR(G7/F6,"")) | I7: =IF(OR(B7="",F7="",F$6="",B$6=""),"",IF((B7-B$6)=0,"",IFERROR((F7/F$6)^(365/(B7-B$6))-1,"")))
B8: 46112 | C8: 146000 | D8: 10400 | E8: 2800 | F8: =IF(B8="","",SUM(C8:E8)) | G8: =IF(B8="","",IFERROR(F8-F7,"")) | H8: =IF(B8="","",IFERROR(G8/F7,"")) | I8: =IF(OR(B8="",F8="",F$6="",B$6=""),"",IF((B8-B$6)=0,"",IFERROR((F8/F$6)^(365/(B8-B$6))-1,"")))
B9: 46142 | C9: 151000 | D9: 11000 | E9: 3000 | F9: =IF(B9="","",SUM(C9:E9)) | G9: =IF(B9="","",IFERROR(F9-F8,"")) | H9: =IF(B9="","",IFERROR(G9/F8,"")) | I9: =IF(OR(B9="",F9="",F$6="",B$6=""),"",IF((B9-B$6)=0,"",IFERROR((F9/F$6)^(365/(B9-B$6))-1,"")))
B10: 46173 | C10: 157500 | D10: 12000 | E10: 3200 | F10: =IF(B10="","",SUM(C10:E10)) | G10: =IF(B10="","",IFERROR(F10-F9,"")) | H10: =IF(B10="","",IFERROR(G10/F9,"")) | I10: =IF(OR(B10="",F10="",F$6="",B$6=""),"",IF((B10-B$6)=0,"",IFERROR((F10/F$6)^(365/(B10-B$6))-1,"")))
B11: 46203 | C11: 161000 | D11: 13200 | E11: 3300 | F11: =IF(B11="","",SUM(C11:E11)) | G11: =IF(B11="","",IFERROR(F11-F10,"")) | H11: =IF(B11="","",IFERROR(G11/F10,"")) | I11: =IF(OR(B11="",F11="",F$6="",B$6=""),"",IF((B11-B$6)=0,"",IFERROR((F11/F$6)^(365/(B11-B$6))-1,"")))
B12: 46223 | C12: 165000 | D12: 14500 | E12: 3500 | F12: =IF(B12="","",SUM(C12:E12)) | G12: =IF(B12="","",IFERROR(F12-F11,"")) | H12: =IF(B12="","",IFERROR(G12/F11,"")) | I12: =IF(OR(B12="",F12="",F$6="",B$6=""),"",IF((B12-B$6)=0,"",IFERROR((F12/F$6)^(365/(B12-B$6))-1,"")))
F13: =IF(B13="","",SUM(C13:E13)) | G13: =IF(B13="","",IFERROR(F13-F12,"")) | H13: =IF(B13="","",IFERROR(G13/F12,"")) | I13: =IF(OR(B13="",F13="",F$6="",B$6=""),"",IF((B13-B$6)=0,"",IFERROR((F13/F$6)^(365/(B13-B$6))-1,"")))
F14: =IF(B14="","",SUM(C14:E14)) | G14: =IF(B14="","",IFERROR(F14-F13,"")) | H14: =IF(B14="","",IFERROR(G14/F13,"")) | I14: =IF(OR(B14="",F14="",F$6="",B$6=""),"",IF((B14-B$6)=0,"",IFERROR((F14/F$6)^(365/(B14-B$6))-1,"")))
F15: =IF(B15="","",SUM(C15:E15)) | G15: =IF(B15="","",IFERROR(F15-F14,"")) | H15: =IF(B15="","",IFERROR(G15/F14,"")) | I15: =IF(OR(B15="",F15="",F$6="",B$6=""),"",IF((B15-B$6)=0,"",IFERROR((F15/F$6)^(365/(B15-B$6))-1,"")))
F16: =IF(B16="","",SUM(C16:E16)) | G16: =IF(B16="","",IFERROR(F16-F15,"")) | H16: =IF(B16="","",IFERROR(G16/F15,"")) | I16: =IF(OR(B16="",F16="",F$6="",B$6=""),"",IF((B16-B$6)=0,"",IFERROR((F16/F$6)^(365/(B16-B$6))-1,"")))
F17: =IF(B17="","",SUM(C17:E17)) | G17: =IF(B17="","",IFERROR(F17-F16,"")) | H17: =IF(B17="","",IFERROR(G17/F16,"")) | I17: =IF(OR(B17="",F17="",F$6="",B$6=""),"",IF((B17-B$6)=0,"",IFERROR((F17/F$6)^(365/(B17-B$6))-1,"")))
F18: =IF(B18="","",SUM(C18:E18)) | G18: =IF(B18="","",IFERROR(F18-F17,"")) | H18: =IF(B18="","",IFERROR(G18/F17,"")) | I18: =IF(OR(B18="",F18="",F$6="",B$6=""),"",IF((B18-B$6)=0,"",IFERROR((F18/F$6)^(365/(B18-B$6))-1,"")))
F19: =IF(B19="","",SUM(C19:E19)) | G19: =IF(B19="","",IFERROR(F19-F18,"")) | H19: =IF(B19="","",IFERROR(G19/F18,"")) | I19: =IF(OR(B19="",F19="",F$6="",B$6=""),"",IF((B19-B$6)=0,"",IFERROR((F19/F$6)^(365/(B19-B$6))-1,"")))
F20: =IF(B20="","",SUM(C20:E20)) | G20: =IF(B20="","",IFERROR(F20-F19,"")) | H20: =IF(B20="","",IFERROR(G20/F19,"")) | I20: =IF(OR(B20="",F20="",F$6="",B$6=""),"",IF((B20-B$6)=0,"",IFERROR((F20/F$6)^(365/(B20-B$6))-1,"")))
F21: =IF(B21="","",SUM(C21:E21)) | G21: =IF(B21="","",IFERROR(F21-F20,"")) | H21: =IF(B21="","",IFERROR(G21/F20,"")) | I21: =IF(OR(B21="",F21="",F$6="",B$6=""),"",IF((B21-B$6)=0,"",IFERROR((F21/F$6)^(365/(B21-B$6))-1,"")))
F22: =IF(B22="","",SUM(C22:E22)) | G22: =IF(B22="","",IFERROR(F22-F21,"")) | H22: =IF(B22="","",IFERROR(G22/F21,"")) | I22: =IF(OR(B22="",F22="",F$6="",B$6=""),"",IF((B22-B$6)=0,"",IFERROR((F22/F$6)^(365/(B22-B$6))-1,"")))
F23: =IF(B23="","",SUM(C23:E23)) | G23: =IF(B23="","",IFERROR(F23-F22,"")) | H23: =IF(B23="","",IFERROR(G23/F22,"")) | I23: =IF(OR(B23="",F23="",F$6="",B$6=""),"",IF((B23-B$6)=0,"",IFERROR((F23/F$6)^(365/(B23-B$6))-1,"")))
F24: =IF(B24="","",SUM(C24:E24)) | G24: =IF(B24="","",IFERROR(F24-F23,"")) | H24: =IF(B24="","",IFERROR(G24/F23,"")) | I24: =IF(OR(B24="",F24="",F$6="",B$6=""),"",IF((B24-B$6)=0,"",IFERROR((F24/F$6)^(365/(B24-B$6))-1,"")))
... F80: =IF(B80="","",SUM(C80:E80)) | G80: =IF(B80="","",IFERROR(F80-F79,"")) | H80: =IF(B80="","",IFERROR(G80/F79,"")) | I80: =IF(OR(B80="",F80="",F$6="",B$6=""),"",IF((B80-B$6)=0,"",IFERROR((F80/F$6)^(365/(B80-B$6))-1,"")))
F81: =IF(B81="","",SUM(C81:E81)) | G81: =IF(B81="","",IFERROR(F81-F80,"")) | H81: =IF(B81="","",IFERROR(G81/F80,""))
B82: 📊 HISTORY INSIGHTS | F82: =IF(B82="","",SUM(C82:E82)) | G82: =IF(B82="","",IFERROR(F82-F81,"")) | H82: =IF(B82="","",IFERROR(G82/F81,""))
B83: Avg Monthly Change | C83: =IFERROR(AVERAGE(G7:G80),0) | F83: =IF(B83="","",SUM(C83:E83)) | G83: =IF(B83="","",IFERROR(F83-F82,"")) | H83: =IF(B83="","",IFERROR(G83/F82,""))
B84: Total Growth | C84: =IFERROR(LOOKUP(2,1/(F6:F80<>""),F6:F80)-F6,0) | F84: =IF(B84="","",SUM(C84:E84)) | G84: =IF(B84="","",IFERROR(F84-F83,"")) | H84: =IF(B84="","",IFERROR(G84/F83,""))
B85: Total Growth % | C85: =IFERROR(C83/F6,0) | F85: =IF(B85="","",SUM(C85:E85)) | G85: =IF(B85="","",IFERROR(F85-F84,"")) | H85: =IF(B85="","",IFERROR(G85/F84,""))
B86: Snapshots Recorded | C86: =COUNTA(B6:B80) | F86: =IF(B86="","",SUM(C86:E86)) | G86: =IF(B86="","",IFERROR(F86-F85,"")) | H86: =IF(B86="","",IFERROR(G86/F85,""))
B87: Best Month (Highest Growth) | C87: =IFERROR(MAX(G7:G80),0) | F87: =IF(B87="","",SUM(C87:E87)) | G87: =IF(B87="","",IFERROR(F87-F86,"")) | H87: =IF(B87="","",IFERROR(G87/F86,""))
B88: Worst Month (Lowest Growth) | C88: =IFERROR(MIN(G7:G80),0) | F88: =IF(B88="","",SUM(C88:E88)) | G88: =IF(B88="","",IFERROR(F88-F87,"")) | H88: =IF(B88="","",IFERROR(G88/F87,""))
F89: =IF(B89="","",SUM(C89:E89)) | G89: =IF(B89="","",IFERROR(F89-F88,"")) | H89: =IF(B89="","",IFERROR(G89/F88,""))
F90: =IF(B90="","",SUM(C90:E90)) | G90: =IF(B90="","",IFERROR(F90-F89,"")) | H90: =IF(B90="","",IFERROR(G90/F89,""))
F91: =IF(B91="","",SUM(C91:E91)) | G91: =IF(B91="","",IFERROR(F91-F90,"")) | H91: =IF(B91="","",IFERROR(G91/F90,""))
F92: =IF(B92="","",SUM(C92:E92)) | G92: =IF(B92="","",IFERROR(F92-F91,"")) | H92: =IF(B92="","",IFERROR(G92/F91,""))
F93: =IF(B93="","",SUM(C93:E93)) | G93: =IF(B93="","",IFERROR(F93-F92,"")) | H93: =IF(B93="","",IFERROR(G93/F92,""))
F94: =IF(B94="","",SUM(C94:E94)) | G94: =IF(B94="","",IFERROR(F94-F93,"")) | H94: =IF(B94="","",IFERROR(G94/F93,""))
F95: =IF(B95="","",SUM(C95:E95)) | G95: =IF(B95="","",IFERROR(F95-F94,"")) | H95: =IF(B95="","",IFERROR(G95/F94,""))
F96: =IF(B96="","",SUM(C96:E96)) | G96: =IF(B96="","",IFERROR(F96-F95,"")) | H96: =IF(B96="","",IFERROR(G96/F95,""))
F97: =IF(B97="","",SUM(C97:E97)) | G97: =IF(B97="","",IFERROR(F97-F96,"")) | H97: =IF(B97="","",IFERROR(G97/F96,""))
...

Sheet README
B1: HOW THIS TRACKER WORKS
B3: A lightweight system for tracking your total money and estimated interest growth.
B5: QUICK START
B6: 1. Open Accounts and replace the sample accounts with your real bank, e-wallet, and cash balances.
B7: 2. Enter the balance currently shown by the institution in Recorded Balance.
B8: 3. Enter the account's interest rate as a percentage, such as 3.50%.
B9: 4. Choose Annual when the published rate is yearly, or Monthly when the rate applies each month.
B10: 5. Set Last Updated to the date the recorded balance was accurate.
B11: 6. Set Include in Total to Yes or No for each account.
B12: 7. The Dashboard uses Calculated Balance Today. Add snapshots to Balance History when you want to preserve progress.
B14: INTEREST CALCULATION
B15: Annual basis: the entered rate is treated as an effective annual rate and converted to an equivalent monthly estimate.
... B48: History Insights: summary metrics at the bottom of Balance History including average change, total growth, best/worst months.
